Workbook

Sheet  Guía de mapeo (problemas)
A1: Nombre del programa o instrumento | B1: Período de implementación | C1: Descripción | D1: Objetivo general | E1: Categoría principal de intervención | F1: Categoría(s) secundaria(s) de intervención | G1: Problema transversal que busca resolver | K1: Institución ejecutora | L1: Año de creación | M1: Años de antiguedad (vs creación) | N1: Columna 1 | O1: Tipo de intervención | P1: Estado actual | Q1: Tipo de instrumento | R1: Mecanismo de entrega | S1: Requisitos de acceso | T1: Población empresarial | U1: Grado de formalidad requerido | W1: Territorio | X1: Enfoque de género | Y1: Indicadores previstos | Z1: Número de beneficiarios (Efectivo) | AA1: Moneda (Presupuesto) | AB1: Presupuesto asignado | AC1: Moneda (Costo por beneficiario) | AD1: Costo por beneficiario | AE1: Fuente de financiamiento | AF1: Productos entregados | AG1: Lecciones aprendidas
A2: SAT (Servicio Asistencia Técnica) | B2: 1997-2005 | C2: Programa estatal de capacitación y asistencia técnica para micro y pequeñas empresas manufactureras y turísticas. Funcionó mediante un sistema de bonos que otorgaba libertad de elección al productor | D2: Fortalecer capacidad artesanal | E2: Asistencia técnica, incubación y fortalecimiento de capacidades | G2: Gestión empresarial y habilidades gerenciales deficientes: Existían marcadas debilidades en la capacidad gerencial, contable, administrativa y de mercado en los micro y pequeños empresarios y artesanos | H2: Trámites y burocracia estatal: El sector industrial enfrentaba impedimentos burocráticos y procesos lentos que frenaban la modernización y la iniciativa empresarial | I2: Inexistencia de un mercado de servicios no financieros: Carecía un mercado transparente y competitivo de consultoría privada y capacitación adaptado a las demandas reales de las micro y pequeñas empresas | J2: Improvisación y elevada mortalidad de negocios: Los emprendimientos nacían con visión de corto plazo y sin acompañamiento técnico, provocando la pérdida prematura de capital | K2: SAT (Entidad) | L2: 1997 | M2: 29 | O2: Capacitación técnica | P2: Concluido | Q2: Asistencia Técnica | R2: Sistema de bonos | S2: Micro y pequeños | T2: Micro y Pequeña | U2: Industrial y Turístico | W2: Nacional | X2: Participación femenina | Z2: 93.463 personas | AA2: USD | AB2: 16350000 | AC2: =AA2 -> USD | AD2: =5750000/93463 -> 61.521672 | AE2: Créditos IDA / BID | AF2: Consultoría especializada | AG2: Los bonos dan libertad de elección al productor
A3: Proyectos FOMIN / BID MyPEs | B3: 1999-2005 | C3: Fondo internacional para canalizar financiamiento y apoyo integral a micro y pequeñas empresas formales, resolviendo la escasez de crédito productivo | D3: Apoyo integral MyPE | E3: Financiamiento y crédito productivo | G3: Restricción y "crunch" de crédito: Las MyPEs formales enfrentaban un severo racionamiento del crédito en el sistema financiero tradicional por falta de garantías convencionales e historial bancario | H3: Ausencia de financiamiento de largo plazo: La oferta crediticia comercial se limitaba a plazos muy cortos e intereses elevados que impedían la inversión en activos fijos | I3: Falta de apoyo integral: Los esfuerzos de financiamiento no estaban acompañados de servicios de asistencia técnica y desarrollo empresarial para garantizar la sostenibilidad y reconversión productiva | K3: BDP-SAM (NAFIBO) | L3: 1999 | M3: =2026-L3 -> 27 | O3: Financiamiento | P3: Concluido | Q3: Crédito | R3: Intermediación | S3: MyPEs formales | T3: Micro y Pequeña | W3: Nacional | Y3: 600 MyPEs | Z3: 12 PYMES | AA3: USD | AB3: 16350000 | AC3: =AA3 -> USD | AD3: =AB3/600 -> 27250 | AE3: BID / FOMIN | AF3: Subprogramas de crédito | AG3: Requería redirección a prioridades
A4: SBPC y Acuerdos de Competitividad (ABC) | B4: 2001 - 2005 | C4: Sistema de concertación público-privada creado para formular políticas de productividad, utilizando los ABC como compromisos mutuos de inversión y competitividad por cadena productiva | D4: Definir visión estratégica y generar cadenas competitivas | E4: Articulación de cadenas, asociatividad e infraestructura productiva | G4: Conflictos y desarticulación público-privada: Falta de espacios institucionales de diálogo concertado y permanente entre empresarios, el gobierno y la academia | H4: Trámites costosos y mal clima de negocios: Trámites burocráticos excesivos, incertidumbre normativa y problemas transversales de infraestructura que restaban competitividad al país | I4: Desconfianza entre eslabones de la cadena: Desarticulación entre los proveedores de materia prima, la industria procesadora y los comercializadores | K4: Unidad de Productividad y Competitividad (UPC) | L4: 2001 (SBPC) / 2002 (ABC) | M4: 25 años desde su creación original | O4: Asociatividad, articulación de cadenas y clusters | P4: Concluido | Q4: Acuerdo Público-Privado / Agenda Responsabilidad (ARCO) | R4: Mesas de concertación y negociación participativa | S4: Ser actor relevante de la cadena productiva seleccionada | T4: Unidades productivas de todos los tamaños en clusters | W4: Nacional, Municipal y Prefectural | Z4: 20 clusters articulados nacionalmente | AE4: Mixto (TGN, CAF, Sector Privado) | AF4: Planes de competitividad y matrices de compromisos | AG4: La institucionalidad compartida es clave para el éxito
A5: PAC (Prog. Apoyo Competitividad) | B5: 2001 -2008 | C5: Iniciativa de la CAF que financió investigación, asistencia técnica y articulación de cadenas o "clusters" de exportación mediante metodologías participativas y talleres | D5: Fortalecer clusters exportación | E5: Articulación de cadenas, asociatividad e infraestructura productiva | G5: Baja competitividad sistémica y dependencia de primarios: Las formas de competir internacionalmente se basaban en ventajas comparativas estáticas (recursos naturales) en lugar de innovación y valor agregado | H5: Desarticulación en cadenas y clusters: Los eslabones de las cadenas productivas de exportación (soya, quinua, madera, textil, cuero, vino) operaban de forma aislada y sin visiones estratégicas compartidas | I5: Cuellos de botella logísticos y de entorno: Existían severas deficiencias en infraestructura de transporte, burocracia aduanera y falta de investigación/tecnología aplicada | K5: UPC | L5: 2001 | M5: 25 | O5: Investigación y Clusters | P5: Concluido | Q5: Asistencia Técnica | R5: Diagnósticos y talleres | S5: Clusters seleccionados | T5: Clusters y OE's | W5: Nacional | Y5: 47 proyectos | Z5: 47 contrapartes | AA5: USD | AB5: 80000 | AC5: =AA5 -> USD | AE5: CAF | AF5: Estudios de cluster | AG5: Compatibiliza intereses diversos
A6: CITEs / CETIPs | B6: 2007 - Presente | C6: Centros públicos especializados de PRO-BOLIVIA que brindan asistencia técnica, capacitación, laboratorios y servicios de maquinado industrial para mejorar la productividad de las MyPEs | D6: Acceso a tecnología aplicada | E6: Innovación tecnológica, digitalización y productividad | G6: Rezago tecnológico en la manufactura básica: Las MyPEs e industrias artesanales sufrían de un atraso considerable en maquinaria, herramientas y metodologías de producción | H6: Dificultad de acceso a infraestructura técnica avanzada: Los pequeños productores no podían costear laboratorios de ensayo de calidad, metrología, diseño asistido o equipos de maquinado industrial | I6: Cuellos de botella en el acabado de productos: Existían deficiencias severas en el acabado, estandarización y control de calidad en complejos clave como madera, textil, cuero, metalmecánica y lácteos | K6: PRO-BOLIVIA | L6: 2017 | M6: =2026-L6 -> 9 | O6: Innovación tecnológica | P6: Vigente | Q6: Infraestructura Servicios | R6: Servicios de laboratorio | S6: Unidades registradas | T6: Micro y Pequeña | W6: Nacional | Y6: 36.926 servicios técnicos | AA6: BOB | AB6: 1036189 | AC6: =AA6 -> BOB | AD6: =AB6/36926 -> 28.061231 | AE6: Recursos públicos | AF6: Prototipos, ensayos | AG6: Clave para industrialización básica
A7: PROLECHE (Fondo de Apoyo) | B7: 2011 - Presente | C7: Fondo que fomenta el complejo lácteo, promueve el consumo de leche y otorga transferencias e infraestructura a productores. Se financia con retenciones a bebidas alcohólicas. | D7: Fomentar complejo lácteo | E7: Financiamiento y crédito productivo | G7: Bajo consumo per cápita de leche: La población boliviana registraba bajos niveles de consumo de lácteos, lo que afectaba la seguridad alimentaria y la nutrición | H7: Inestabilidad y precios injustos para el productor: Existían asimetrías de poder de negociación entre las industrias procesadoras y los pequeños productores lecheros primarios | I7: Deficiencias técnicas y de infraestructura: Los pequeños lecheros carecían de equipamiento adecuado (tanques de enfriamiento, ordeñadoras) y centros de acopio para garantizar la calidad de la leche cruda | K7: PRO-BOLIVIA | L7: 2011 | M7: =2026-L7 -> 15 | O7: Subvención e infraestructura | P7: Vigente | Q7: Transferencia no reembolsable | R7: Equipos e infraestructura | S7: Certificación precio justo | T7: Productores lácteos | U7: Industrias registradas | W7: Nacional | Y7: 16 unidades productivas lácteas | AA7: BOB | AB7: 26400000 | AC7: =AA7 -> BOB | AD7: =AB7/16 -> 1650000 | AE7: Retenciones bebidas alcohólicas | AF7: Centros de acopio | AG7: Apoyo condicionado al precio justo
A8: Fideicomisos Sectoriales y Multisectoriales (Incluye FDP, FIP y Líneas Sectoriales BDP) | B8: 2007 - Presente | C8: Patrimonios autónomos estatales operados por el BDP para canalizar financiamiento a sectores productivos estratégicos, promoviendo innovación tecnológica y sostenibilidad en micro y medianas unidades productivas | D8: Financiar las prioridades productivas y estratégicas del Estado | E8: Financiamiento y crédito productivo | G8: Subinversión en complejos productivos estratégicos: Existía una persistente falta de financiamiento de fomento a largo plazo para rubros clave de la economía (agrícola, ganadero, avícola, quinua, azúcar, etc.) | H8: Exclusión del crédito bancario comercial: Productores micro, pequeños y medianos, así como organizaciones económicas comunitarias, estaban marginados del crédito en condiciones adecuadas | I8: Vulnerabilidad ante eventos climáticos: La pérdida recurrente de capital de operaciones e inversión por sequías, inundaciones u otros desastres naturales ponía en riesgo la continuidad productiva | K8: BDP-S.A.M. (Fiduciario) | L8: 2007 | M8: 19 | O8: Financiamiento e intermediación financiera | P8: Vigente | Q8: Fideicomisos de Crédito (Patrimonios Autónomos) | R8: Desembolsos vía ventanillas de primer y segundo piso | S8: NIT activo, proyecto viable y pertenencia a rubros priorizados | T8: Micro, Pequeños y Medianos productores y organizaciones | U8: Unidades y organizaciones legalmente constituidas | W8: Nacional | X8: Transversal | Y8: Saldo de cartera bruta y operaciones vigentes | Z8: 2.318 operaciones activas | AA8: BOB | AB8: 584060000 | AC8: =AA8 -> BOB | AD8: =AB8/2318 -> 251967.21 | AE8: Tesoro General de la Nación (TGN) y recursos BDP | AF8: Créditos para capital de inversión y operaciones | AG8: Los fideicomisos permiten instrumentalizar la política de manera ágil
A9: AL-INVEST 5.0 (Bolivia) | B9: 2016-2020 | C9: Programa europeo liderado por CAINCO que elevó la productividad y competitividad de Mipymes a través de asistencia técnica grupal y núcleos empresariales asociativos | D9: Desarrollo sostenible mipymes | E9: Financiamiento y crédito productivo | G9: Baja productividad y brechas de innovación regional: Las Mipymes presentaban serios rezagos en sus procesos productivos, gestión ambiental y acceso a mercados internacionales | H9: Aislamiento e individualismo empresarial: Predominaba el trabajo aislado, impidiendo la colaboración horizontal para comprar materias primas o vender en volumen | I9: Debilidad de las organizaciones empresariales (OE): Las cámaras y gremios del sector privado carecían de metodologías estandarizadas y sostenibles para transferir conocimientos técnicos a sus asociados | K9: Consorcios (CAINCO) | L9: 2016 | M9: =2026-L9 -> 10 | O9: Productividad y mercados | P9: Concluido | Q9: Asistencia Técnica grupal | R9: Núcleos empresariales | S9: Mipymes en gremios | T9: Mipymes | W9: Nacional | X9: Mujeres empoderadas | Z9: 3.939 Mipymes (Bol) | AA9: EUR | AB9: 3038747.3 | AC9: =AA9 -> EUR | AD9: =AB9/3939 -> 771.45147 | AE9: Unión Europea | AF9: Servicios OE, certificados | AG9: "Sector apoya a sector" funciona
A10: PROMYPE Fase II | B10: 2017-2023 | C10: Programa de PRO-BOLIVIA que fortalece MyPEs manufactureras urbanas y periurbanas mediante asistencia técnica, capacitación y la transferencia directa de maquinaria | D10: Fortalecer capacidades e innovación | E10: Asistencia técnica, incubación y fortalecimiento de capacidades | G10: Baja productividad por maquinaria obsoleta: Las MyPEs manufactureras urbanas y periurbanas operaban con equipamiento antiguo que elevaba los costos y reducía la calidad | H10: Limitada capacidad de inversión propia: Las microempresas no contaban con capital suficiente para adquirir maquinaria o tecnología de producción limpia por sí solas | I10: Deficiencias de formación técnica y gestión: Faltaban programas integrales que combinaran la entrega de activos productivos con capacitación y bonos de asistencia técnica | K10: PRO-BOLIVIA | L10: 2021 | M10: =2026-L10 -> 5 | O10: Asistencia técnica y activos | P10: En ejecución | Q10: Subvención / Cofinanciamiento | R10: Transferencia de maquinaria y bonos | S10: Registro en PRO-BOLIVIA | T10: MYPE | U10: Unidades registradas | W10: Nacional | X10: 40% a 50% mujeres | Y10: 1.278 MYPEs | AA10: BOB | AB10: 3500000 | AC10: =AA10 -> BOB | AD10: =AB10/1278 -> 2738.6541 | AE10: Mixto (TGN/COSUDE) | AF10: Maquinaria, capacitación | AG10: El modelo de bonos es altamente efectivo
A11: Sello "Hecho en Bolivia" | B11: 2017 - Presente | C11: Registro y acreditación oficial para unidades productivas nacionales, permitiéndoles acceder a mercados internos y preferenciales en compras públicas del Estado | D11: Acreditar unidades para compras | E11: Formalización, certificación, acceso a mercados e internacionalización | G11: Preferencia por lo importado y contrabando: Existía una débil cultura de consumo de la producción nacional y una fuerte presión competitiva del contrabando y productos importados | H11: Barreras de acceso a compras estatales: Las MyPEs y artesanos enfrentaban dificultades formales y comerciales para colocar sus bienes en los catálogos del Estado y obtener márgenes de preferencia | I11: Falta de acreditación y certificación de origen: Las unidades económicas no contaban con un registro simplificado que certificara el componente nacional de sus productos | K11: PRO-BOLIVIA | L11: 2017 | M11: 9 | O11: Formalización y mercados | P11: Vigente | Q11: Registro / Sello | R11: Certificado Registro | S11: NIT activo | T11: Micro y Pequeña | U11: Formales | W11: Nacional | Y11: 3.000 solicitudes | Z11: 15.111 MyPymes | AA11: BOB | AB11: 360082 | AC11: =AA11 -> BOB | AD11: =AB11/15111 -> 23.829131 | AE11: Recursos públicos | AF11: Certificado acreditación | AG11: Facilita la compra estatal a las MyPEs
A12: Proyecto Mercados Inclusivos | B12: 2018 - 2024 | C12: Proyecto financiado por cooperación suiza y sueca que promueve el desarrollo de modelos de negocio, servicios financieros y microseguros adaptados al cambio climático para productores rurales | D12: Mejorar ingresos y empleo | E12: Articulación de cadenas, asociatividad e infraestructura productiva | G12: Ineficiencia y vulnerabilidad en cadenas rurales: Los pequeños productores rurales de valles y altiplano enfrentaban bajos ingresos por su débil articulación a mercados de consumo e insumos | H12: Riesgo y vulnerabilidad climática sin cobertura: Inexistencia de productos financieros adaptados, como microseguros agrícolas o créditos verdes, frente a sequías y heladas | I12: Desigualdad de género: Las mujeres rurales enfrentaban brechas marcadas para acceder a servicios financieros y participar activamente en la gestión comercial | K12: Swisscontact / Helvetas | L12: 2020 | M12: 6 | O12: Modelos de negocio | P12: En ejecución | Q12: Asistencia Técnica | R12: Capacitación | S12: Emprendedores | T12: MyPEs y Productores | W12: La Paz, Oruro, Potosí, Sucre y Tarija | X12: Empoderamiento mujer | Z12: 25.000 personas | AA12: USD | AB12: 8300000 | AC12: =AA12 -> USD | AD12: =AB12/25000 -> 332 | AE12: Cooperación Int. | AF12: Modelos de negocio | AG12: Enfoque de multidimensionalidad de la pobreza
A13: PAR III (Alianzas Rurales) | B13: 2022 - 2027 | C13: Programa del MDRyT que realiza transferencias público-privadas de infraestructura y tecnología a pequeños productores organizados de áreas rurales vulnerables para mejorar su acceso a mercados | D13: Mejorar acceso a mercados rurales | E13: Articulación de cadenas, asociatividad e infraestructura productiva | G13: Pobreza rural y aislamiento comercial: Pequeños productores agropecuarios marginados no lograban colocar su producción en condiciones ventajosas de mercado | H13: Déficit de infraestructura productiva rural: Falta de caminos vecinales, sistemas de riego, centros de acopio y equipamiento para mitigar riesgos ambientales y garantizar entregas estables | I13: Falta de acuerdos directos con compradores: Inexistencia de alianzas estratégicas formales entre las organizaciones de productores y las industrias o mercados formales | K13: EMPODERAR | L13: 2023 | M13: 3 | O13: Infraestructura y mercados | P13: En ejecución | Q13: Transferencia público-privada | R13: Planes de alianzas | S13: Pequeños productores | T13: Pequeños productores | W13: Nacional (Rural) | X13: Género / Jóvenes | Y13: 23.865 productores | Z13: 247.503 personas | AA13: BOB | AB13: 8.759488e+08 | AC13: =AA13 -> BOB | AD13: =AB13/247865 -> 3533.9753 | AE13: Crédito externo / TGN | AF13: Infraestructura productiva | AG13: Alianzas rurales generan empleo rural sostenible
A14: BDP Lab (Incubadora) | B14: 2019 - Presente | C14: Incubadora de negocios del BDP que ofrece mentoría, coworking y asistencia técnica personalizada para perfeccionar planes de negocio y facilitar el acceso a capital semilla. | D14: Despegue de emprendimientos | E14: Asistencia técnica, incubación y fortalecimiento de capacidades | G14: Falta de acreditación y certificación de origen: Las unidades económicas no contaban con un registro simplificado que certificara el componente nacional de sus productos | H14: Improvisación y falta de validación de mercado: Los nuevos negocios salían al mercado sin haber probado previamente sus prototipos ni haber recibido mentoria técnica | I14: Desconexión con redes de apoyo e inversión: Los innovadores no disponían de espacios de coworking ni de aceleración para conectarse con otros actores del ecosistema emprendedor
A15: SIBOLIVIA (Fideicomiso FIREDIN) | B15: 2020 - Presente | C15: Fideicomiso estatal que financia capital de operaciones o inversión para la sustitución de importaciones, ofreciendo una tasa de interés fija anual del 0,5% | D15: Industrialización con sustitución de importaciones | E15: Financiamiento y crédito productivo | G15: Parálisis productiva y crisis de liquidez post-pandemia: Las unidades productivas sufrieron una severa iliquidez y contracción de la demanda tras las emergencias sanitarias y económicas | H15: Alta dependencia de importaciones: La industria nacional importaba volumen considerable de insumos, materias primas y bienes finales que podían ser elaborados localmente | I15: Costo elevado del crédito bancario para reactivación: Las tasas de interés comerciales resultaban inviables para empresas golpeadas que requerían crédito blando para sustituir importaciones | K15: BDP-S.A.M. y Banco Unión S.A. | L15: 2020 | M15: 6 | O15: Financiamiento directo (Crédito) | P15: En ejecución | Q15: Crédito con tasa de interés fija del 0,5% anual | R15: Ventanilla bancaria (BDP y Banco Unión) | S15: NIT activo y proyecto de producción nacional | T15: Micro, Pequeña, Mediana y Gran Empresa | U15: Unidades económicas formales | W15: Nacional | X15: Transversal | Z15: 6.145 unidades productivas | AA15: BOB | AB15: 2393364000 | AC15: =AA15 -> BOB | AD15: =AB15/6145 -> 389481.53 | AE15: Tesoro General de la Nación (TGN) - Fideicomiso | AF15: Desembolsos para capital de inversión y operaciones | AG15: Tasas bajas aceleran la industrialización
A16: Capital Semilla (FOCASE) | B16: 2021 - Presente | C16: Fondo administrado por el BDP que otorga financiamiento y créditos de arranque a nuevos emprendimientos de profesionales, técnicos o microproductores, utilizando utilidades de la banca. | D16: Financiar etapas iniciales | E16: Financiamiento y crédito productivo | G16: Exclusión de emprendimientos nacientes: El sistema bancario tradicional rechazaba solicitudes de crédito para negocios en etapa inicial o embrionaria por la falta de historial financiero o estados financieros auditados | H16: Barreras para jóvenes profesionales y técnicos: Existía un universo de estudiantes, técnicos e innovadores con capacidad de emprendimiento pero sin acceso a un "capital de arranque" | I16: Alta mortandad de empresas: Gran parte de los emprendimientos quebraba antes de consolidarse al tener que recurrir a prestamistas informales o agotar sus ahorros | K16: BDP-SAM | L16: 2017 | M16: =2026-L16 -> 9 | O16: Financiamiento | P16: Vigente | Q16: Crédito | R16: Desembolso directo | S16: Título o aval de formación | T16: Emprendimientos | U16: Formales/En proceso | W16: Nacional | X16: Prioriza mujeres | Y16: 2.072 operaciones | Z16: 3.462 operaciones | AA16: BOB | AB16: 785224246 | AC16: =AA16 -> BOB | AD16: =AB16/3462 -> 226812.32 | AE16: Utilidades banca (3% y 6%) | AF16: Créditos de arranque | AG16: Fondo vital para diversificación
A17: LaPazTec (Prog. Municipal) | B17: 2021-Presente | C17: Programa municipal de La Paz para promover el emprendimiento tecnológico en jóvenes y retener talento, facilitando mentorías y créditos de infraestructura en la nube de AWS. | D17: Emprendimiento tecnológico | E17: Innovación tecnológica, digitalización y productividad | G17: Fuga de talento joven e innovador: Pérdida de capacidades y emprendedores tecnológicos que migran o abandonan proyectos por falta de apoyo local | H17: Alta mortandad de startups tecnológicas: Fracaso temprano de emprendimientos digitales por falta de espacios de aceleración, mentorías especializadas y financiamiento de infraestructura en la nube (AWS)
A18: Ecoeficiencia BDP | B18: 2022 - Presente | C18: Créditos sostenibles dirigidos a pymes y grandes empresas para financiar proyectos de energía renovable, eficiencia energética y reducción de residuos químicos peligrosos. | D18: Financiar transición energética | E18: Sostenibilidad, transición verde y economía circular | G18: Inadecuada gestión energética y ambiental en la industria: Altos costos operativos por consumo ineficiente de electricidad, combustibles y agua, y mala gestión de residuos contaminantes . | H18: Inexistencia de oferta crediticia verde: El sistema financiero tradicional no ofrecía préstamos blando con condiciones específicas para proyectos de eficiencia energética o tecnologías bajas en carbono | K18: GAMLP (DTI) | L18: 2025 | M18: 1 | O18: Innovación y emprendimiento | P18: En ejecución | Q18: Incubación / Concurso | R18: Bootcamp y mentoría | S18: Residentes en La Paz | T18: Startups y jóvenes | U18: Ideas y Startups | W18: La Paz | X18: Inclusivo | AA18: BOB | AB18: 945954 | AC18: =AA18 -> BOB | AD18: 5000 | AE18: Presupuesto municipal | AF18: Créditos nube (AWS) | AG18: La retención de talento requiere infraestructura nube
A19: BID Invest / Banco FIE (2022) | B19: 2022 - Presente | C19: Línea de crédito comercial externa de USD 35 millones para ampliar el financiamiento formal y reducir brechas de acceso al crédito de las MiPymes de Bolivia | D19: Línea de Crédito MiPymes | E19: Financiamiento y crédito productivo | G19: Brecha de crédito comercial privado: Insuficiente oferta de liquidez bancaria de mediano plazo dedicada de forma exclusiva al crecimiento de las MiPymes en el sistema privado | H19: Barreras para la escala empresarial: Dificultades de las pequeñas empresas para acceder a montos de inversión requeridos para su expansión productiva | K19: Banco FIE | L19: 2022 | M19: 4 | O19: Financiamiento | P19: Vigente | Q19: Crédito | R19: Ventanilla bancaria | S19: Ser cliente MiPyme FIE | T19: MiPymes | U19: Formales | W19: Nacional | AA19: USD | AB19: 35000000 | AC19: =AA19 -> USD | AE19: BID Invest | AF19: Créditos productivos | AG19: Alta participación de FIE en garantías BDP (51%)
A20: Santa Cruz Distrito ZERO | B20: 24 meses | C20: Iniciativa de AL-INVEST Verde en Santa Cruz enfocada en guiar a pymes hacia la economía circular, la ecoeficiencia y estrategias de residuo cero | E20: Sostenibilidad, transición verde y economía circular | G20: Alta generación e ineficiencia en el manejo de residuos: Las Pymes cruceñas desechaban volumen considerable de residuos aprovechables, incrementando la contaminación y los costos de operación . | H20: Desconocimiento de la economía circular: Falta de asistencia técnica diagnóstica para reintroducir residuos en los procesos de producción y alcanzar metas de "residuo cero" . | K20: Cámara Cantabria | L20: 2024 | M20: =2026-L20 -> 2 | O20: Economía circular | P20: En ejecución | Q20: Asistencia Técnica | R20: Diagnósticos | S20: Pymes de Santa Cruz | T20: MYPE | W20: Santa Cruz | Y20: 200 MiPymes | AA20: EUR | AB20: 374920.3 | AC20: =AA20 -> EUR | AD20: =AB20/200 -> 1874.6015 | AE20: Unión Europea | AF20: Estrategias residuo cero
A21: Vía Verde (AL-INVEST Verde) | B21: 23 meses | C21: Proyecto de AL-INVEST Verde que asiste a pymes agroforestales para obtener certificaciones internacionales y cumplir con exigencias ambientales europeas para la exportación sostenible | E21: Formalización, certificación, acceso a mercados e internacionalización | G21: Nuevas barreras de acceso a la Unión Europea: Exigencias estrictas de no deforestación, huella de carbono e inocuidad impuestas a los productos agroforestales | H21: Deficiencias de información y plataforma de exportación: Las Mipymes agroforestales carecían de orientación digital y capacitación para cumplir con las normativas internacionales | K21: IBCE | L21: 2024 | M21: =2026-L21 -> 2 | O21: Certificación y exportación | P21: En ejecución | Q21: Capacitación / Certificación | R21: Misiones técnicas | S21: Mipymes agroforestales | T21: MiPymes | W21: Santa Cruz | X21: Mujeres y jóvenes | Y21: 150 MiPymes | AA21: EUR | AB21: 375000 | AC21: =AA21 -> EUR | AD21: =AB21/150 -> 2500 | AE21: Unión Europea | AF21: Certificaciones export
A22: Iniciativa 3i Bolivia / Cono Sur | B22: 2024-2026 | C22: Proyecto de AL-INVEST Verde orientado a la transición ecológica de pymes bolivianas, promoviendo modelos de negocio sostenibles de triple impacto en el sur del país | E22: Sostenibilidad, transición verde y economía circular | G22: Modelos productivos ambientalmente insostenibles: Las Pymes agroindustriales operaban bajo esquemas convencionales que generaban deforestación y altas emisiones | H22: Falta de transición hacia el triple impacto: Dificultad para integrar la sostenibilidad ambiental y social como un factor de ventaja competitiva en regiones vulnerables como el sur de Bolivia | I22: Barreras de certificación ecológica: Ausencia de sellos y trazabilidad ambiental requeridos para posicionar productos en mercados de exportación | K22: Ayuda en Acción | L22: 2024 | M22: =2026-L22 -> 2 | O22: Transición verde | P22: En ejecución | Q22: Asistencia y Finanzas | R22: Servicios empresariales | S22: Pymes con potencial | T22: MiPymes y asoc. | W22: Chuq, Tja, Pot, LP | Y22: 378 Mipymes | AA22: EUR | AB22: 375000 | AC22: =AA22 -> EUR | AD22: =AB22/378 -> 992.06349 | AE22: Unión Europea | AF22: Mipymes verdes fortalecidas

Sheet Tabla de problemas e instrument
A1: Categoría de problemas | B1: Problema identificado (por recurrencia) | C1: Tipo de instrumento | D1: Instrumento / herramienta | E1: Programa (instrumento específico) | F1: Calidad y confianza de la información
A2: Asistencia técnica, incubación y fortalecimiento de capacidades | B2: 2. Gestión empresarial y habilidades gerenciales deficientes | C2: Subvención a la demanda e incentivos individuales (Bonos / Vouchers) | D2: Sistema de Bonos subsidiados | E2: SAT (Servicio Asistencia Técnica) (Sistema de Bonos subsidiados)
C3: Fortalecimiento de consultores e intermediarios (ICAPs y Cámaras) | D3: Registro de Instituciones de Capacitación (ICAPs) | E3: SAT (Servicio Asistencia Técnica) (Registro de Instituciones de Capacitación (ICAPs))
C4: Asistencia técnica, incubación y fortalecimiento de capacidades | D4: Programa "Mejorar" | E4: SAT (Servicio Asistencia Técnica) (Programa "Mejorar")
A5: Asistencia técnica, incubación y fortalecimiento de capacidades | B5: 4. Improvisación y elevada mortalidad de negocios | C5: Incubación, mentores y aceleración de emprendimientos | D5: Programa "Emprender" | E5: SAT (Servicio Asistencia Técnica) (Programa "Emprender")
C6: Investigación aplicada, desarrollo de prototipos y concursos | D6: Programa "Innovar" | E6: SAT (Servicio Asistencia Técnica) (Programa "Innovar")
C7: Asociatividad y redes empresariales (Clusters y Núcleos) | D7: Programas "Asociar" y "Mercados" | E7: SAT (Servicio Asistencia Técnica) (Programas "Asociar" y "Mercados")
A8: Asistencia técnica, incubación y fortalecimiento de capacidades | B8: 6. Alta mortandad de startups tecnológicas | C8: Incubación, mentores y aceleración de emprendimientos | D8: Bootcamps Intensivos y Mentorías Especializadas | E8: LaPazTec (Prog. Municipal) (Bootcamps Intensivos y Mentorías Especializadas)
C9: Investigación aplicada, desarrollo de prototipos y concursos | D9: Evento "Pitch Elevator" | E9: LaPazTec (Prog. Municipal) (Evento "Pitch Elevator")
C10: Digitalización, plataformas informáticas e inteligencia productiva | D10: Créditos en Servicios de Nube de AWS | E10: LaPazTec (Prog. Municipal) (Créditos en Servicios de Nube de AWS)
A11: Asistencia técnica, incubación y fortalecimiento de capacidades | B11: 7. Inexistencia de un mercado de servicios no financieros | C11: Fortalecimiento de consultores e intermediarios (ICAPs y Cámaras) | D11: Mecanismo Institucional de Tercer Piso | E11: SAT (Servicio Asistencia Técnica) (Mecanismo Institucional de Tercer Piso)
C12: Fortalecimiento de consultores e intermediarios (ICAPs y Cámaras) | D12: Programa "Apoyo a la Oferta" | E12: SAT (Servicio Asistencia Técnica) (Programa "Apoyo a la Oferta")
A13: Asistencia técnica, incubación y fortalecimiento de capacidades | B13: 19. Deficiencias de formación técnica y gestión | C13: Subvención a la demanda e incentivos individuales (Bonos / Vouchers) | D13: Bonos de Asistencia Técnica en Planta | E13: PROMYPE Fase II (Bonos de Asistencia Técnica en Planta)
C14: Diagnósticos, auditorías ambientales y medición de impacto | D14: Diagnósticos de Producción Más Limpia (PML) | E14: PROMYPE Fase II (Diagnósticos de Producción Más Limpia (PML))
A15: Asistencia técnica, incubación y fortalecimiento de capacidades | B15: 23. Improvisación y falta de validación de mercado | C15: Investigación aplicada, desarrollo de prototipos y concursos | D15: Pruebas de Aceptabilidad de Producto | E15: BDP Lab (Incubadora) (Pruebas de Aceptabilidad de Producto)
C16: Digitalización, plataformas informáticas e inteligencia productiva | D16: Plataformas de Asistencia Digital | E16: BDP Lab (Incubadora) (Plataformas de Asistencia Digital)
A17: Asistencia técnica, incubación y fortalecimiento de capacidades | B17: 31. Falta de apoyo integral | C17: Subvenciones, transferencias y cofinanciamiento no reembolsable | D17: Componente de Cooperación Técnica No Reembolsable | E17: Proyectos FOMIN / BID MyPEs (Componente de Cooperación Técnica No Reembolsable)
A18: Asistencia técnica, incubación y fortalecimiento de capacidades | B18: 42. Desigualdad de género | C18: Desarrollo de sistemas de mercado con enfoque social y género | D18: Módulo de Empoderamiento Económico de la Mujer | E18: Proyecto Mercados Inclusivos (Módulo de Empoderamiento Económico de la Mujer)
A19: Asistencia técnica, incubación y fortalecimiento de capacidades | B19: 48. Exclusión de emprendimientos nacientes | C19: Capital semilla, riesgo e incubación financiera | D19: Fondo FOCASE (RM 055/2017 / DS 3459) | E19: Capital Semilla (FOCASE) (Fondo FOCASE (RM 055/2017 / DS 3459))
A20: Asistencia técnica, incubación y fortalecimiento de capacidades | B20: 49. Barreras para jóvenes profesionales y técnicos | C20: Capital semilla, riesgo e incubación financiera | D20: Criterios de Elegibilidad por Capital Humano | E20: Capital Semilla (FOCASE) (Criterios de Elegibilidad por Capital Humano)
A21: Asistencia técnica, incubación y fortalecimiento de capacidades | B21: 50. Alta mortandad de empresas | C21: Capital semilla, riesgo e incubación financiera | D21: Créditos Directos de Despegue | E21: Capital Semilla (FOCASE) (Créditos Directos de Despegue)
A22: Asistencia técnica, incubación y fortalecimiento de capacidades | B22: 51. Fuga de talento joven e innovador | C22: Investigación aplicada, desarrollo de prototipos y concursos | D22: Convocatoria Pública "Reto LaPazTec Bicentenario" | E22: LaPazTec (Prog. Municipal) (Convocatoria Pública "Reto LaPazTec Bicentenario")
A23: Formalización, certificación, acceso a mercados e internacionalización | B23: 1. Falta de acreditación y certificación de origen | C23: Marcas país, registro de origen y sello de producción nacional | D23: Sistema de Registro y Acreditación Digital de PRO-BOLIVIA | E23: Sello "Hecho en Bolivia" (Sistema de Registro y Acreditación Digital de PRO-BOLIVIA)
C24: Incubación, mentores y aceleración de emprendimientos | D24: Programa de Incubación BDP Lab | E24: BDP Lab (Incubadora) (Programa de Incubación BDP Lab)
C25: Incubación, mentores y aceleración de emprendimientos | D25: Mentorías Personalizadas | E25: BDP Lab (Incubadora) (Mentorías Personalizadas)
A26: Formalización, certificación, acceso a mercados e internacionalización | B26: 3. Trámites y burocracia estatal | C26: Asistencia técnica, incubación y fortalecimiento de capacidades | D26: Programa "Informar" | E26: SAT (Servicio Asistencia Técnica) (Programa "Informar")
C27: Adecuación normativa e internacionalización | D27: Cédula Empresarial | E27: SAT (Servicio Asistencia Técnica) (Cédula Empresarial)
C28: Asistencia técnica, incubación y fortalecimiento de capacidades | D28: Oficinas Regionales Desconcentradas | E28: SAT (Servicio Asistencia Técnica) (Oficinas Regionales Desconcentradas)
A29: Formalización, certificación, acceso a mercados e internacionalización | B29: 5. Bajo consumo per cápita de leche | C29: Subvenciones, transferencias y cofinanciamiento no reembolsable | D29: Fondo PROLECHE (Ley 204 / DS 1207) | E29: PROLECHE (Fondo de Apoyo) (Fondo PROLECHE (Ley 204 / DS 1207))
C30: Subvenciones, transferencias y cofinanciamiento no reembolsable | D30: Mecanismos de Recaudación (RCC y RIBA) | E30: PROLECHE (Fondo de Apoyo) (Mecanismos de Recaudación (RCC y RIBA))
C31: Promoción comercial, ferias y eventos de mercado | D31: Campañas Masivas de Promoción del Consumo | E31: PROLECHE (Fondo de Apoyo) (Campañas Masivas de Promoción del Consumo)
A32: Formalización, certificación, acceso a mercados e internacionalización | B32: 15. Inestabilidad y precios injustos para el productor | C32: Adecuación normativa e internacionalización | D32: Certificado de Precio Justo (CPJ) | E32: PROLECHE (Fondo de Apoyo) (Certificado de Precio Justo (CPJ))
C33: Subvenciones, transferencias y cofinanciamiento no reembolsable | D33: Transferencias Directas Monetarias | E33: PROLECHE (Fondo de Apoyo) (Transferencias Directas Monetarias)
A34: Formalización, certificación, acceso a mercados e internacionalización | B34: 20. Preferencia por lo importado y contrabando | C34: Marcas país, registro de origen y sello de producción nacional | D34: Certificado y Sello Oficial "Hecho en Bolivia" | E34: Sello "Hecho en Bolivia" (Certificado y Sello Oficial "Hecho en Bolivia")
C35: Promoción comercial, ferias y eventos de mercado | D35: Campañas de Promoción Comercial | E35: Sello "Hecho en Bolivia" (Campañas de Promoción Comercial)
A36: Formalización, certificación, acceso a mercados e internacionalización | B36: 21. Barreras de acceso a compras estatales | C36: Preferencias comerciales e inclusión en compras estatales | D36: Margen de Preferencia del 20% | E36: Sello "Hecho en Bolivia" (Margen de Preferencia del 20%)
C37: Preferencias comerciales e inclusión en compras estatales | D37: Catálogo Electrónico "Compro Hecho en Bolivia" | E37: Sello "Hecho en Bolivia" (Catálogo Electrónico "Compro Hecho en Bolivia")
A38: Formalización, certificación, acceso a mercados e internacionalización | B38: 28. Deficiencias de información y plataforma de exportación | C38: Adecuación normativa e internacionalización | D38: Plataforma Digital de Orientación Exportadora Sostenible | E38: Vía Verde (AL-INVEST Verde) (Plataforma Digital de Orientación Exportadora Sostenible)
C39: Promoción comercial, ferias y eventos de mercado | D39: Campañas de Comunicación Internacional | E39: Vía Verde (AL-INVEST Verde) (Campañas de Comunicación Internacional)
A40: Formalización, certificación, acceso a mercados e internacionalización | B40: 32. Trámites costosos y mal clima de negocios | C40: Adecuación normativa e internacionalización | D40: Programa Nacional de Simplificación de Trámites | E40: SBPC y Acuerdos de Competitividad (ABC) (Programa Nacional de Simplificación de Trámites)
...

Sheet Recurrencia y cobertura
A1: Categoría | B1: Cantidad Problemas | C1: % de recurrencia | D1: Cobertura | E1: Cobertura promedio
A2: Asistencia técnica, incubación y fortalecimiento de capacidades | B2: =COUNTIF('Tabla de problemas e instrument'!A2:A101,A2) -> 12 | C2: =B2/SUM($B$2:$B$7) -> 0.20689655 | D2: =SUMPRODUCT(--(LOOKUP(ROW('Tabla de problemas e instrument'!$A$2:$A$94),ROW('Tabla de problemas e instrument'!$A$2:$A$94)/('Tabla de problemas e instrument'!$A$2:$A$94<>""),'Tabla de problemas e instrument'!$A$2:$A$94)=A2),--('Tabla de problemas e instrument'!$D$2:$D$94<>"")) -> 21 | E2: =D2/B2 -> 1.75
A3: Formalización, certificación, acceso a mercados e internacionalización | B3: =COUNTIF('Tabla de problemas e instrument'!A4:A103,A3) -> 12 | C3: =B3/SUM($B$2:$B$7) -> 0.20689655 | D3: =SUMPRODUCT(--(LOOKUP(ROW('Tabla de problemas e instrument'!$A$2:$A$94),ROW('Tabla de problemas e instrument'!$A$2:$A$94)/('Tabla de problemas e instrument'!$A$2:$A$94<>""),'Tabla de problemas e instrument'!$A$2:$A$94)=A3),--('Tabla de problemas e instrument'!$D$2:$D$94<>"")) -> 22 | E3: =D3/B3 -> 1.8333333
A4: Articulación de cadenas, asociatividad e infraestructura productiva | B4: =COUNTIF('Tabla de problemas e instrument'!A5:A104,A4) -> 10 | C4: =B4/SUM($B$2:$B$7) -> 0.17241379 | D4: =SUMPRODUCT(--(LOOKUP(ROW('Tabla de problemas e instrument'!$A$2:$A$94),ROW('Tabla de problemas e instrument'!$A$2:$A$94)/('Tabla de problemas e instrument'!$A$2:$A$94<>""),'Tabla de problemas e instrument'!$A$2:$A$94)=A4),--('Tabla de problemas e instrument'!$D$2:$D$94<>"")) -> 16 | E4: =D4/B4 -> 1.6
A5: Financiamiento y crédito productivo | B5: =COUNTIF('Tabla de problemas e instrument'!A7:A106,A5) -> 10 | C5: =B5/SUM($B$2:$B$7) -> 0.17241379 | D5: =SUMPRODUCT(--(LOOKUP(ROW('Tabla de problemas e instrument'!$A$2:$A$94),ROW('Tabla de problemas e instrument'!$A$2:$A$94)/('Tabla de problemas e instrument'!$A$2:$A$94<>""),'Tabla de problemas e instrument'!$A$2:$A$94)=A5),--('Tabla de problemas e instrument'!$D$2:$D$94<>"")) -> 13 | E5: =D5/B5 -> 1.3
A6: Innovación tecnológica, digitalización y productividad | B6: =COUNTIF('Tabla de problemas e instrument'!A3:A102,A6) -> 7 | C6: =B6/SUM($B$2:$B$7) -> 0.12068966 | D6: =SUMPRODUCT(--(LOOKUP(ROW('Tabla de problemas e instrument'!$A$2:$A$94),ROW('Tabla de problemas e instrument'!$A$2:$A$94)/('Tabla de problemas e instrument'!$A$2:$A$94<>""),'Tabla de problemas e instrument'!$A$2:$A$94)=A6),--('Tabla de problemas e instrument'!$D$2:$D$94<>"")) -> 11 | E6: =D6/B6 -> 1.5714286
A7: Sostenibilidad, transición verde y economía circular | B7: =COUNTIF('Tabla de problemas e instrument'!A6:A105,A7) -> 7 | C7: =B7/SUM($B$2:$B$7) -> 0.12068966 | D7: =SUMPRODUCT(--(LOOKUP(ROW('Tabla de problemas e instrument'!$A$2:$A$94),ROW('Tabla de problemas e instrument'!$A$2:$A$94)/('Tabla de problemas e instrument'!$A$2:$A$94<>""),'Tabla de problemas e instrument'!$A$2:$A$94)=A7),--('Tabla de problemas e instrument'!$D$2:$D$94<>"")) -> 10 | E7: =D7/B7 -> 1.4285714

Sheet Frecuencia de instrumentos
A1: Ranking | B1: Tipo de instrumento | C1: Categoría analítica | D1: Nº de apariciones | E1: % del total | F1: Nivel de recurrencia
A2: 1 | B2: Subvenciones, transferencias y cofinanciamiento no reembolsable | C2: Financiamiento y crédito productivo | D2: 11 | E2: 11,83% | F2: Alta
A3: 2 | B3: Crédito de fomento y liquidez a tasas preferenciales | C3: Financiamiento y crédito productivo | D3: 8 | E3: 8,60% | F3: Alta
A4: 3 | B4: Investigación aplicada, desarrollo de prototipos y concursos | C4: Innovación tecnológica, digitalización y productividad | D4: 7 | E4: 7,53% | F4: Alta
A5: 4 | B5: Mesas de concertación, acuerdos e institucionalidad compartida | C5: Articulación de cadenas, asociatividad e infraestructura productiva | D5: 7 | E5: 7,53% | F5: Alta
A6: 5 | B6: Adecuación normativa e internacionalización | C6: Formalización, certificación, acceso a mercados e internacionalización | D6: 5 | E6: 5,38% | F6: Alta
A7: 6 | B7: Diagnósticos, auditorías ambientales y medición de impacto | C7: Sostenibilidad, transición verde y economía circular | D7: 5 | E7: 5,38% | F7: Alta
A8: 7 | B8: Incubación, mentores y aceleración de emprendimientos | C8: Asistencia técnica, incubación y fortalecimiento de capacidades | D8: 5 | E8: 5,38% | F8: Alta
A9: 8 | B9: Asistencia técnica, incubación y fortalecimiento de capacidades | C9: Asistencia técnica, incubación y fortalecimiento de capacidades | D9: 4 | E9: 4,30% | F9: Media
A10: 9 | B10: Asociatividad y redes empresariales (Clusters y Núcleos) | C10: Articulación de cadenas, asociatividad e infraestructura productiva | D10: 4 | E10: 4,30% | F10: Media
A11: 10 | B11: Capital semilla, riesgo e incubación financiera | C11: Financiamiento y crédito productivo | D11: 4 | E11: 4,30% | F11: Media
A12: 11 | B12: Fortalecimiento de consultores e intermediarios (ICAPs y Cámaras) | C12: Asistencia técnica, incubación y fortalecimiento de capacidades | D12: 4 | E12: 4,30% | F12: Media
A13: 12 | B13: Centros tecnológicos, plantas piloto y laboratorios compartidos | C13: Innovación tecnológica, digitalización y productividad | D13: 3 | E13: 3,23% | F13: Media
... A25: 24 | B25: Infraestructura productiva, logística y equipamiento físico | C25: Articulación de cadenas, asociatividad e infraestructura productiva | D25: 1 | E25: 1,08% | F25: Baja
B26: Total | D26: 93 | E26: 1

Sheet Calidad y confianza
A1: Instrumentos/Herramientas | B1: Fuente identificada | C1: Autoridad de la fuente | D1: Datos verificables sobre el programa | E1: Descripción del programa | F1: Distinción de hechos y resultados | G1: Fecha identificable y vigencia de programas | H1: Información sustantiva
A2: SAT (Servicio Asistencia Técnica) (Sistema de Bonos subsidiados) | B2: CEPAL. (2009). Políticas para la inserción laboral de mujeres y jóvenes en el Estado Plurinacional de Bolivia. Colección Documentos de Proyectos, Santiago de Chile. | C2: Si | D2: Si | E2: Si | F2: Si | G2: Si | H2: Si
A3: SAT (Servicio Asistencia Técnica) (Registro de Instituciones de Capacitación (ICAPs)) | B3: CEPAL. (2009). Políticas para la inserción laboral de mujeres y jóvenes en el Estado Plurinacional de Bolivia. Colección Documentos de Proyectos. | C3: Si | D3: Si | E3: Si | F3: Si | G3: Si | H3: Si
A4: SAT (Servicio Asistencia Técnica) (Programa "Mejorar") | B4: Ministerio de Desarrollo Productivo y Economía Plural (MDPyEP) & OIT. (2020). Lineamientos Ampliados de la Política Industrial de Bolivia. La Paz. | C4: Si | D4: Si | E4: Si | F4: Si | G4: Si | H4: Si
A5: SAT (Servicio Asistencia Técnica) (Programa "Emprender") | B5: Ministerio de Desarrollo Productivo y Economía Plural (MDPyEP) & OIT. (2020). Lineamientos Ampliados de la Política Industrial de Bolivia. La Paz. | C5: Si | D5: Si | E5: Si | F5: Si | G5: Si | H5: Si
A6: SAT (Servicio Asistencia Técnica) (Programa "Innovar") | B6: Ministerio de Desarrollo Productivo y Economía Plural (MDPyEP) & OIT. (2020). Lineamientos Ampliados de la Política Industrial de Bolivia. La Paz. | C6: Si | D6: Si | E6: Si | F6: Si | G6: Si | H6: Si
A7: SAT (Servicio Asistencia Técnica) (Programas "Asociar" y "Mercados") | B7: CEPAL. (2009). Políticas para la inserción laboral de mujeres y jóvenes en el Estado Plurinacional de Bolivia. Colección Documentos de Proyectos. | C7: Si | D7: Si | E7: Si | F7: Si | G7: Si | H7: Si
A8: LaPazTec (Prog. Municipal) (Bootcamps Intensivos y Mentorías Especializadas) | B8: Gobierno Autónomo Municipal de La Paz (GAMLP). (2025). Convocatoria Reto LAPAZTEC AWS del Bicentenario. Dirección de Tecnologías de la Información. La Paz. | C8: Si | D8: Si | E8: Si | F8: Si | G8: Si | H8: Si
A9: LaPazTec (Prog. Municipal) (Evento "Pitch Elevator") | B9: GAMLP & Open Government Partnership (OGP). (2025). LaPazTec: Programa para promover el emprendimiento tecnológico (BOLPB0006). La Paz. | C9: Si | D9: Si | E9: Si | F9: Si | G9: Si | H9: Si
A10: LaPazTec (Prog. Municipal) (Créditos en Servicios de Nube de AWS) | B10: Gobierno Autónomo Municipal de La Paz (GAMLP). (2025). Convocatoria Reto LAPAZTEC AWS del Bicentenario. La Paz. | C10: Si | D10: Si | E10: Si | F10: Si | G10: Si | H10: Si
A11: SAT (Servicio Asistencia Técnica) (Mecanismo Institucional de Tercer Piso) | B11: CEPAL. (2009). Políticas para la inserción laboral de mujeres y jóvenes en el Estado Plurinacional de Bolivia. Colección Documentos de Proyectos. | C11: Si | D11: Si | E11: Si | F11: Si | G11: Si | H11: Si
A12: SAT (Servicio Asistencia Técnica) (Programa "Apoyo a la Oferta") | B12: CEPAL. (2009). Políticas para la inserción laboral de mujeres y jóvenes en el Estado Plurinacional de Bolivia. Colección Documentos de Proyectos. | C12: Si | D12: Si | E12: Si | F12: Si | G12: Si | H12: Si
... A94: Iniciativa 3i Bolivia / Cono Sur (Diagnósticos Ambientales Diagnósticos) | B94: CNI, CAINCO & Ayuda en Acción. (2024). Diagnósticos de Sostenibilidad Ambiental. La Paz. | C94: Si | D94: Si | E94: Si | F94: Si | G94: Si | H94: Si

Sheet Info de entrevistas
A1: Grupo de soluciones | B1: Descripción breve | C1: Menciones | D1: Entradas (en marcha / hipotéticas)
A2: Conocimiento y capacidades (familia) | B2: Soluciones que transfieren conocimiento o capacidades a la empresa, a sus dueños o a su entorno. Se presentan en tres subgrupos que forman una misma familia. | C2: 14/25 | D2: 36 (19 / 17)
A3: Formación y acompañamiento | B3: Mentoría sostenida, consultor individual asignado, educación ejecutiva, formación en el lugar de trabajo, aceleración, docentes practitioners e intervenciones puntuales de diagnóstico en planta. | C3: 11/25 | D3: 19 (8 / 11)
A4: Demostración y aprendizaje entre pares | B4: Foros y benchmarks, ferias de exhibición, casos de éxito como padrinos, comunidades de usuarios, difusión de buenas prácticas existentes y alianzas de innovación abierta universidad-empresa. | C4: 10/25 | D4: 14 (10 / 4)
A5: Adaptación de tecnología | B5: Copiar y validar tecnología de contextos comparables, con adaptación local previa a su adopción. | C5: 2/25 | D5: 3 (1 / 2)
A6: Cambiar las reglas | B6: Reformas normativas, tributarias, laborales, societarias y sectoriales, y cambios en subsidios o regulación, que modifican el marco en que operan las empresas. | C6: 14/25 | D6: 28 (4 / 24)
A7: Conectar oferta y demanda | B7: Mecanismos que articulan al productor con un comprador o mercado: empresa ancla, agregadores, cooperativas, garantías de compra y precio, promoción comercial y mercados regionales o de exportación. | C7: 13/25 | D7: 19 (11 / 8)
A8: Financiar | B8: Instrumentos que proveen capital o reducen su costo: crédito, garantías, seguros paramétricos, capital de riesgo, fondos, financiamiento verde y esquemas de coparticipación en el costo. | C8: 12/25 | D8: 21 (6 / 15)
A9: Organizar el ecosistema | B9: Arreglos institucionales y de coordinación: champion, entidad ejecutora con Estado veedor, gobernanza separada de la gestión, instancias de diálogo, acuerdos de competitividad y puerta de entrada a la oferta pública. | C9: 12/25 | D9: 20 (6 / 14)
A10: Reposicionar la oferta | B10: Cambios en qué y cómo se ofrece: nichos de alto valor, subir un escalón en la cadena, subproductos y economía circular, servicios exportables y valoración de servicios ambientales. | C10: 11/25 | D10: 23 (6 / 17)
A11: Infraestructura y plataformas | B11: Infraestructura física, energética y digital habilitante: factura electrónica y datos de la MiPyme, pagos QR, software de gestión, alojamiento turístico y energía. | C11: 11/25 | D11: 17 (9 / 8)
